<?xml version="1.0" encoding="UTF-8"?>
<testng-results skipped="0" failed="3" ignored="0" total="8" passed="5">
  <reporter-output>
  </reporter-output>
  <suite name="Default suite" duration-ms="8452" started-at="2019-03-01T12:11:48Z" finished-at="2019-03-01T12:11:56Z">
    <groups>
    </groups>
    <test name="Default test" duration-ms="8452" started-at="2019-03-01T12:11:48Z" finished-at="2019-03-01T12:11:56Z">
      <class name="com.EmployeManagement.tests.EmployeeManagementTest">
        <test-method status="PASS" signature="deleteEmployeeWithJSONStringTest()[pri:0, instance:com.EmployeManagement.tests.EmployeeManagementTest@cb5822]" name="deleteEmployeeWithJSONStringTest" duration-ms="3525" started-at="2019-03-01T12:11:48Z" finished-at="2019-03-01T12:11:51Z">
          <reporter-output>
          </reporter-output>
        </test-method> <!-- deleteEmployeeWithJSONStringTest -->
        <test-method status="FAIL" signature="deleteEmployeeWithPayloadTest()[pri:0, instance:com.EmployeManagement.tests.EmployeeManagementTest@cb5822]" name="deleteEmployeeWithPayloadTest" duration-ms="3043" started-at="2019-03-01T12:11:51Z" finished-at="2019-03-01T12:11:54Z">
          <exception class="java.lang.AssertionError">
            <message>
              <![CDATA[expected [200] but found [204]]]>
            </message>
            <full-stacktrace>
              <![CDATA[java.lang.AssertionError: expected [200] but found [204]
at org.testng.Assert.fail(Assert.java:96)
at org.testng.Assert.failNotEquals(Assert.java:776)
at org.testng.Assert.assertEqualsImpl(Assert.java:137)
at org.testng.Assert.assertEquals(Assert.java:118)
at org.testng.Assert.assertEquals(Assert.java:652)
at org.testng.Assert.assertEquals(Assert.java:662)
at com.EmployeManagement.tests.EmployeeManagementTest.deleteEmployeeWithPayloadTest(EmployeeManagementTest.java:48)
at sun.reflect.NativeMethodAccessorImpl.invoke0(Native Method)
at sun.reflect.NativeMethodAccessorImpl.invoke(Unknown Source)
at sun.reflect.DelegatingMethodAccessorImpl.invoke(Unknown Source)
at java.lang.reflect.Method.invoke(Unknown Source)
at org.testng.internal.MethodInvocationHelper.invokeMethod(MethodInvocationHelper.java:124)
at org.testng.internal.Invoker.invokeMethod(Invoker.java:583)
at org.testng.internal.Invoker.invokeTestMethod(Invoker.java:719)
at org.testng.internal.Invoker.invokeTestMethods(Invoker.java:989)
at org.testng.internal.TestMethodWorker.invokeTestMethods(TestMethodWorker.java:125)
at org.testng.internal.TestMethodWorker.run(TestMethodWorker.java:109)
at org.testng.TestRunner.privateRun(TestRunner.java:648)
at org.testng.TestRunner.run(TestRunner.java:505)
at org.testng.SuiteRunner.runTest(SuiteRunner.java:455)
at org.testng.SuiteRunner.runSequentially(SuiteRunner.java:450)
at org.testng.SuiteRunner.privateRun(SuiteRunner.java:415)
at org.testng.SuiteRunner.run(SuiteRunner.java:364)
at org.testng.SuiteRunnerWorker.runSuite(SuiteRunnerWorker.java:52)
at org.testng.SuiteRunnerWorker.run(SuiteRunnerWorker.java:84)
at org.testng.TestNG.runSuitesSequentially(TestNG.java:1208)
at org.testng.TestNG.runSuitesLocally(TestNG.java:1137)
at org.testng.TestNG.runSuites(TestNG.java:1049)
at org.testng.TestNG.run(TestNG.java:1017)
at org.testng.remote.AbstractRemoteTestNG.run(AbstractRemoteTestNG.java:114)
at org.testng.remote.RemoteTestNG.initAndRun(RemoteTestNG.java:251)
at org.testng.remote.RemoteTestNG.main(RemoteTestNG.java:77)
]]>
            </full-stacktrace>
          </exception> <!-- java.lang.AssertionError -->
          <reporter-output>
          </reporter-output>
        </test-method> <!-- deleteEmployeeWithPayloadTest -->
        <test-method status="PASS" signature="getAllEmployeesTest()[pri:0, instance:com.EmployeManagement.tests.EmployeeManagementTest@cb5822]" name="getAllEmployeesTest" duration-ms="1046" started-at="2019-03-01T12:11:54Z" finished-at="2019-03-01T12:11:55Z">
          <reporter-output>
          </reporter-output>
        </test-method> <!-- getAllEmployeesTest -->
        <test-method status="PASS" signature="getEmployeeTest()[pri:0, instance:com.EmployeManagement.tests.EmployeeManagementTest@cb5822]" name="getEmployeeTest" duration-ms="296" started-at="2019-03-01T12:11:55Z" finished-at="2019-03-01T12:11:56Z">
          <reporter-output>
          </reporter-output>
        </test-method> <!-- getEmployeeTest -->
        <test-method status="PASS" signature="postEmployeeWithJSONStringTest()[pri:0, instance:com.EmployeManagement.tests.EmployeeManagementTest@cb5822]" name="postEmployeeWithJSONStringTest" duration-ms="132" started-at="2019-03-01T12:11:56Z" finished-at="2019-03-01T12:11:56Z">
          <reporter-output>
          </reporter-output>
        </test-method> <!-- postEmployeeWithJSONStringTest -->
        <test-method status="FAIL" signature="postEmployeeWithPayloadTest()[pri:0, instance:com.EmployeManagement.tests.EmployeeManagementTest@cb5822]" name="postEmployeeWithPayloadTest" duration-ms="53" started-at="2019-03-01T12:11:56Z" finished-at="2019-03-01T12:11:56Z">
          <exception class="java.lang.AssertionError">
            <message>
              <![CDATA[expected [200] but found [204]]]>
            </message>
            <full-stacktrace>
              <![CDATA[java.lang.AssertionError: expected [200] but found [204]
at org.testng.Assert.fail(Assert.java:96)
at org.testng.Assert.failNotEquals(Assert.java:776)
at org.testng.Assert.assertEqualsImpl(Assert.java:137)
at org.testng.Assert.assertEquals(Assert.java:118)
at org.testng.Assert.assertEquals(Assert.java:652)
at org.testng.Assert.assertEquals(Assert.java:662)
at com.EmployeManagement.tests.EmployeeManagementTest.postEmployeeWithPayloadTest(EmployeeManagementTest.java:28)
at sun.reflect.NativeMethodAccessorImpl.invoke0(Native Method)
at sun.reflect.NativeMethodAccessorImpl.invoke(Unknown Source)
at sun.reflect.DelegatingMethodAccessorImpl.invoke(Unknown Source)
at java.lang.reflect.Method.invoke(Unknown Source)
at org.testng.internal.MethodInvocationHelper.invokeMethod(MethodInvocationHelper.java:124)
at org.testng.internal.Invoker.invokeMethod(Invoker.java:583)
at org.testng.internal.Invoker.invokeTestMethod(Invoker.java:719)
at org.testng.internal.Invoker.invokeTestMethods(Invoker.java:989)
at org.testng.internal.TestMethodWorker.invokeTestMethods(TestMethodWorker.java:125)
at org.testng.internal.TestMethodWorker.run(TestMethodWorker.java:109)
at org.testng.TestRunner.privateRun(TestRunner.java:648)
at org.testng.TestRunner.run(TestRunner.java:505)
at org.testng.SuiteRunner.runTest(SuiteRunner.java:455)
at org.testng.SuiteRunner.runSequentially(SuiteRunner.java:450)
at org.testng.SuiteRunner.privateRun(SuiteRunner.java:415)
at org.testng.SuiteRunner.run(SuiteRunner.java:364)
at org.testng.SuiteRunnerWorker.runSuite(SuiteRunnerWorker.java:52)
at org.testng.SuiteRunnerWorker.run(SuiteRunnerWorker.java:84)
at org.testng.TestNG.runSuitesSequentially(TestNG.java:1208)
at org.testng.TestNG.runSuitesLocally(TestNG.java:1137)
at org.testng.TestNG.runSuites(TestNG.java:1049)
at org.testng.TestNG.run(TestNG.java:1017)
at org.testng.remote.AbstractRemoteTestNG.run(AbstractRemoteTestNG.java:114)
at org.testng.remote.RemoteTestNG.initAndRun(RemoteTestNG.java:251)
at org.testng.remote.RemoteTestNG.main(RemoteTestNG.java:77)
]]>
            </full-stacktrace>
          </exception> <!-- java.lang.AssertionError -->
          <reporter-output>
          </reporter-output>
        </test-method> <!-- postEmployeeWithPayloadTest -->
        <test-method status="PASS" signature="putEmployeeWithJSONStringTest()[pri:0, instance:com.EmployeManagement.tests.EmployeeManagementTest@cb5822]" name="putEmployeeWithJSONStringTest" duration-ms="103" started-at="2019-03-01T12:11:56Z" finished-at="2019-03-01T12:11:56Z">
          <reporter-output>
          </reporter-output>
        </test-method> <!-- putEmployeeWithJSONStringTest -->
        <test-method status="FAIL" signature="putEmployeeWithPayloadTest()[pri:0, instance:com.EmployeManagement.tests.EmployeeManagementTest@cb5822]" name="putEmployeeWithPayloadTest" duration-ms="69" started-at="2019-03-01T12:11:56Z" finished-at="2019-03-01T12:11:56Z">
          <exception class="java.lang.AssertionError">
            <message>
              <![CDATA[expected [200] but found [204]]]>
            </message>
            <full-stacktrace>
              <![CDATA[java.lang.AssertionError: expected [200] but found [204]
at org.testng.Assert.fail(Assert.java:96)
at org.testng.Assert.failNotEquals(Assert.java:776)
at org.testng.Assert.assertEqualsImpl(Assert.java:137)
at org.testng.Assert.assertEquals(Assert.java:118)
at org.testng.Assert.assertEquals(Assert.java:652)
at org.testng.Assert.assertEquals(Assert.java:662)
at com.EmployeManagement.tests.EmployeeManagementTest.putEmployeeWithPayloadTest(EmployeeManagementTest.java:38)
at sun.reflect.NativeMethodAccessorImpl.invoke0(Native Method)
at sun.reflect.NativeMethodAccessorImpl.invoke(Unknown Source)
at sun.reflect.DelegatingMethodAccessorImpl.invoke(Unknown Source)
at java.lang.reflect.Method.invoke(Unknown Source)
at org.testng.internal.MethodInvocationHelper.invokeMethod(MethodInvocationHelper.java:124)
at org.testng.internal.Invoker.invokeMethod(Invoker.java:583)
at org.testng.internal.Invoker.invokeTestMethod(Invoker.java:719)
at org.testng.internal.Invoker.invokeTestMethods(Invoker.java:989)
at org.testng.internal.TestMethodWorker.invokeTestMethods(TestMethodWorker.java:125)
at org.testng.internal.TestMethodWorker.run(TestMethodWorker.java:109)
at org.testng.TestRunner.privateRun(TestRunner.java:648)
at org.testng.TestRunner.run(TestRunner.java:505)
at org.testng.SuiteRunner.runTest(SuiteRunner.java:455)
at org.testng.SuiteRunner.runSequentially(SuiteRunner.java:450)
at org.testng.SuiteRunner.privateRun(SuiteRunner.java:415)
at org.testng.SuiteRunner.run(SuiteRunner.java:364)
at org.testng.SuiteRunnerWorker.runSuite(SuiteRunnerWorker.java:52)
at org.testng.SuiteRunnerWorker.run(SuiteRunnerWorker.java:84)
at org.testng.TestNG.runSuitesSequentially(TestNG.java:1208)
at org.testng.TestNG.runSuitesLocally(TestNG.java:1137)
at org.testng.TestNG.runSuites(TestNG.java:1049)
at org.testng.TestNG.run(TestNG.java:1017)
at org.testng.remote.AbstractRemoteTestNG.run(AbstractRemoteTestNG.java:114)
at org.testng.remote.RemoteTestNG.initAndRun(RemoteTestNG.java:251)
at org.testng.remote.RemoteTestNG.main(RemoteTestNG.java:77)
]]>
            </full-stacktrace>
          </exception> <!-- java.lang.AssertionError -->
          <reporter-output>
          </reporter-output>
        </test-method> <!-- putEmployeeWithPayloadTest -->
      </class> <!-- com.EmployeManagement.tests.EmployeeManagementTest -->
    </test> <!-- Default test -->
  </suite> <!-- Default suite -->
</testng-results>
